Traceback (most recent call last):
  File "D:\psychopy\lib\site-packages\urllib3\connectionpool.py", line 696, in urlopen
    self._prepare_proxy(conn)
  File "D:\psychopy\lib\site-packages\urllib3\connectionpool.py", line 964, in _prepare_proxy
    conn.connect()
  File "D:\psychopy\lib\site-packages\urllib3\connection.py", line 364, in connect
    conn = self._connect_tls_proxy(hostname, conn)
  File "D:\psychopy\lib\site-packages\urllib3\connection.py", line 501, in _connect_tls_proxy
    socket = ssl_wrap_socket(
  File "D:\psychopy\lib\site-packages\urllib3\util\ssl_.py", line 453, in ssl_wrap_socket
    ssl_sock = _ssl_wrap_socket_impl(sock, context, tls_in_tls)
  File "D:\psychopy\lib\site-packages\urllib3\util\ssl_.py", line 495, in _ssl_wrap_socket_impl
    return ssl_context.wrap_socket(sock)
  File "D:\psychopy\lib\ssl.py", line 500, in wrap_socket
    return self.sslsocket_class._create(
  File "D:\psychopy\lib\ssl.py", line 1040, in _create
    self.do_handshake()
  File "D:\psychopy\lib\ssl.py", line 1309, in do_handshake
    self._sslobj.do_handshake()
ssl.SSLEOFError: EOF occurred in violation of protocol (_ssl.c:1131)

During handling of the above exception, another exception occurred:

Traceback (most recent call last):
  File "D:\psychopy\lib\site-packages\requests\adapters.py", line 439, in send
    resp = conn.urlopen(
  File "D:\psychopy\lib\site-packages\urllib3\connectionpool.py", line 755, in urlopen
    retries = retries.increment(
  File "D:\psychopy\lib\site-packages\urllib3\util\retry.py", line 574, in increment
    raise MaxRetryError(_pool, url, error or ResponseError(cause))
urllib3.exceptions.MaxRetryError: HTTPSConnectionPool(host='pavlovia.org', port=443): Max retries exceeded with url: /api/v2/designers/Idle_Mr.Xin (Caused by SSLError(SSLEOFError(8, 'EOF occurred in violation of protocol (_ssl.c:1131)')))

During handling of the above exception, another exception occurred:

Traceback (most recent call last):
  File "D:\psychopy\lib\site-packages\psychopy\app\ribbon.py", line 467, in onMenu
    menu = menu(self, evt)
  File "D:\psychopy\lib\site-packages\psychopy\app\ribbon.py", line 695, in makeMenu
    user = pavlovia.getCurrentSession().user
  File "D:\psychopy\lib\site-packages\psychopy\projects\pavlovia.py", line 465, in user
    self._user = User(self.gitlab.user.username)
  File "D:\psychopy\lib\site-packages\psychopy\projects\pavlovia.py", line 154, in __init__
    self.info = self.session.session.get(
  File "D:\psychopy\lib\site-packages\requests\sessions.py", line 555, in get
    return self.request('GET', url, **kwargs)
  File "D:\psychopy\lib\site-packages\requests\sessions.py", line 542, in request
    resp = self.send(prep, **send_kwargs)
  File "D:\psychopy\lib\site-packages\requests\sessions.py", line 655, in send
    r = adapter.send(request, **kwargs)
  File "D:\psychopy\lib\site-packages\requests\adapters.py", line 514, in send
    raise SSLError(e, request=request)
requests.exceptions.SSLError: HTTPSConnectionPool(host='pavlovia.org', port=443): Max retries exceeded with url: /api/v2/designers/Idle_Mr.Xin (Caused by SSLError(SSLEOFError(8, 'EOF occurred in violation of protocol (_ssl.c:1131)')))
